<?xml version="1.0"?>
<robot name="my_robot">

    <!-- Init colour -->
    <material name="black">
        <color rgba="0.0 0.0 0.0 1.0"/>
    </material>

    <material name="dark">
        <color rgba="0.3 0.3 0.3 1.0"/>
    </material>

    <material name="light_black">
        <color rgba="0.4 0.4 0.4 1.0"/>
    </material>

    <material name="blue">
        <color rgba="0.0 0.0 0.8 1.0"/>
    </material>

    <material name="green">
        <color rgba="0.0 0.8 0.0 1.0"/>
    </material>

    <material name="grey">
        <color rgba="0.5 0.5 0.5 1.0"/>
    </material>

    <material name="orange">
        <color rgba="1.0 0.4235 0.0392 1.0"/>
    </material>

    <material name="brown">
        <color rgba="0.8706 0.8118 0.7647 1.0"/>
    </material>

    <material name="red">
        <color rgba="0.8 0.0 0.0 1.0"/>
    </material>

    <material name="white">
        <color rgba="1.0 1.0 1.0 1.0"/>
    </material>
    
    <!-- base_footprint (projection of base_link on the ground) -->

    <link name="base_footprint"/>
    
    <joint name="base_joint" type="fixed">
        <parent link="base_footprint"/>
        <child link="base_link"/>
        <origin xyz="0 0 0.2" rpy="0 0 0"/>
    </joint>
    
    <!-- base_link and base_scan (required for Nav2) -->

    <link name="base_link">
        <visual>
            <geometry>
                <box size="0.6 0.4 0.2" />
            </geometry>
            <origin xyz="0 0 0" rpy="0 0 0" />
            <material name="blue" />
        </visual>
    </link>
    
    <joint name="base_scan_joint" type="fixed">
        <parent link="base_link"/>
        <child link="base_scan"/>
        <origin xyz="0 0 0.13" rpy="0 0 0"/>
    </joint>
    
    <link name="base_scan">
        <visual>
            <geometry>
                <cylinder radius="0.1" length="0.06"/>
            </geometry>
            <origin xyz="0 0 0" rpy="0 0 0" />
            <material name="orange" />
        </visual>
    </link>
    
    <!-- Wheels -->
    <joint name="base_left_front_wheel_joint" type="continuous">
        <parent link="base_link"/>
        <child link="left_front_wheel"/>
        <origin xyz="0.1 0.2 -0.1" rpy="0 0 0"/>
        <axis xyz="0 1 0"/>
    </joint>

    <link name="left_front_wheel">
        <visual>
            <geometry>
                <cylinder radius="0.1" length="0.05"/>
            </geometry>
            <origin xyz="0 0 0" rpy="1.57 0 0" />
            <material name="white" />
        </visual>
    </link>
    
    <joint name="base_right_front_wheel_joint" type="continuous">
        <parent link="base_link"/>
        <child link="right_front_wheel"/>
        <origin xyz="0.1 -0.2 -0.1" rpy="0 0 0"/>
        <axis xyz="0 1 0"/>
    </joint>

    <link name="right_front_wheel">
        <visual>
            <geometry>
                <cylinder radius="0.1" length="0.05"/>
            </geometry>
            <origin xyz="0 0 0" rpy="1.57 0 0" />
            <material name="white" />
        </visual>
    </link>    

    <joint name="base_left_rear_wheel_joint" type="continuous">
        <parent link="base_link"/>
        <child link="left_rear_wheel"/>
        <origin xyz="-0.1 0.2 -0.1" rpy="0 0 0"/>
        <axis xyz="0 1 0"/>
    </joint>

    <link name="left_rear_wheel">
        <visual>
            <geometry>
                <cylinder radius="0.1" length="0.05"/>
            </geometry>
            <origin xyz="0 0 0" rpy="1.57 0 0" />
            <material name="white" />
        </visual>
    </link>
    
    <joint name="base_right_rear_wheel_joint" type="continuous">
        <parent link="base_link"/>
        <child link="right_rear_wheel"/>
        <origin xyz="-0.1 -0.2 -0.1" rpy="0 0 0"/>
        <axis xyz="0 1 0"/>
    </joint>

    <link name="right_rear_wheel">
        <visual>
            <geometry>
                <cylinder radius="0.1" length="0.05"/>
            </geometry>
            <origin xyz="0 0 0" rpy="1.57 0 0" />
            <material name="white" />
        </visual>
    </link>
    
    <!-- <joint name="base_caster_wheel_joint" type="fixed">
        <parent link="base_link"/>
        <child link="caster_wheel"/>
        <origin xyz="0.2 0 -0.15" rpy="0 0 0"/>
    </joint>

    <link name="caster_wheel">
        <visual>
            <geometry>
                <sphere radius="0.05"/>
            </geometry>
            <origin xyz="0 0 0" rpy="0 0 0" />
            <material name="grey" />
        </visual>
    </link> -->

</robot>
